'''
TASK [Make fruit] **************************************************************
fatal: [waiwera]: FAILED! => {"changed": false, "cmd": "/usr/bin/make", "msg": "make: mpif90: Command not found\nmake: *** [src/fruit.o] Error 127", "rc": 2, "stderr": "make: mpif90: Command not found\nmake: *** [src/fruit.o] Error 127\n", "stderr_lines": ["make: mpif90: Command not found", "make: *** [src/fruit.o] Error 127"], "stdout": "mpif90 -c -fpic -O3 -c src/fruit.f90 -o src/fruit.o\nmakefile:25: recipe for target 'src/fruit.o' failed\n", "stdout_lines": ["mpif90 -c -fpic -O3 -c src/fruit.f90 -o src/fruit.o", "makefile:25: recipe for target 'src/fruit.o' failed"]}
	to retry, use: --limit @/vagrant/ansible/main.retry

PLAY RECAP *********************************************************************
waiwera                    : ok=29   changed=19   unreachable=0    failed=1
'''
fixed through updating the path

'''
TASK [Make the supermodels-test] ***********************************************
fatal: [waiwera]: FAILED! => {"changed": false, "cmd": "/usr/bin/make", "msg": "makefile:4: /lib/petsc/conf/variables: No such file or directory\nmakefile:5: /lib/petsc/conf/rules: No such file or directory\nmake: *** No rule to make target '/lib/petsc/conf/rules'.  Stop.", "rc": 2, "stderr": "makefile:4: /lib/petsc/conf/variables: No such file or directory\nmakefile:5: /lib/petsc/conf/rules: No such file or directory\nmake: *** No rule to make target '/lib/petsc/conf/rules'.  Stop.\n", "stderr_lines": ["makefile:4: /lib/petsc/conf/variables: No such file or directory", "makefile:5: /lib/petsc/conf/rules: No such file or directory", "make: *** No rule to make target '/lib/petsc/conf/rules'.  Stop."], "stdout": "", "stdout_lines": []}
	to retry, use: --limit @/vagrant/ansible/main.retry

PLAY RECAP *********************************************************************
waiwera                    : ok=36   changed=23   unreachable=0    failed=1

Ansible failed to complete successfully. Any error output should be
visible above. Please fix these errors and try again.
'''

the unit tests then run if you ssh in to the vm and run the 'python unit_tests.py' commnad

I think for some reason the path is slow to update for this command
